<?xml version='1.0' encoding='utf-8'?>
<robot name="generated_robot">
  <link name="arm_base_link">
    <inertial>
      <origin xyz="0.22450072 0 -0.69163253" rpy="0 0 0" />
      <mass value="4.8552447" />
      <inertia ixx="0.031680203" iyy="0.029660428" izz="0.045672081" ixy="0" ixz="-0.00025796263" iyz="0" />
    </inertial>
    <visual>
      <origin xyz="0 0 0" rpy="1.5707963 0 0" />
      <geometry>
        <mesh filename="meshes/part_005_surface_shell_005.stl" scale="0.001 0.001 0.001" />
      </geometry>
    </visual>
    <visual>
      <origin xyz="0 0 0" rpy="1.5707963 0 0" />
      <geometry>
        <mesh filename="meshes/part_002_surface_shell_002.stl" scale="0.001 0.001 0.001" />
      </geometry>
    </visual>
    <collision>
      <origin xyz="0 0 0" rpy="1.5707963 0 0" />
      <geometry>
        <mesh filename="meshes/part_005_surface_shell_005.stl" scale="0.001 0.001 0.001" />
      </geometry>
    </collision>
    <collision>
      <origin xyz="0 0 0" rpy="1.5707963 0 0" />
      <geometry>
        <mesh filename="meshes/part_002_surface_shell_002.stl" scale="0.001 0.001 0.001" />
      </geometry>
    </collision>
  </link>
  <link name="arm_link1">
    <inertial>
      <origin xyz="-0.010768995 7.2684119e-10 0.022543009" rpy="0 0 0" />
      <mass value="12.615124" />
      <inertia ixx="0.074294709" iyy="0.083647857" izz="0.0776843" ixy="8.2726716e-10" ixz="-0.00096139675" iyz="6.2949787e-11" />
    </inertial>
    <visual>
      <origin xyz="-0.22962916 0 0.54062108" rpy="1.5707963 0 0" />
      <geometry>
        <mesh filename="meshes/part_003_surface_shell_003.stl" scale="0.001 0.001 0.001" />
      </geometry>
    </visual>
    <visual>
      <origin xyz="-0.22962916 0 0.54062108" rpy="1.5707963 0 0" />
      <geometry>
        <mesh filename="meshes/part_004_surface_shell_004.stl" scale="0.001 0.001 0.001" />
      </geometry>
    </visual>
    <visual>
      <origin xyz="-0.22962916 0 0.54062108" rpy="1.5707963 0 0" />
      <geometry>
        <mesh filename="meshes/part_006_surface_shell_006.stl" scale="0.001 0.001 0.001" />
      </geometry>
    </visual>
    <collision>
      <origin xyz="-0.22962916 0 0.54062108" rpy="1.5707963 0 0" />
      <geometry>
        <mesh filename="meshes/part_003_surface_shell_003.stl" scale="0.001 0.001 0.001" />
      </geometry>
    </collision>
    <collision>
      <origin xyz="-0.22962916 0 0.54062108" rpy="1.5707963 0 0" />
      <geometry>
        <mesh filename="meshes/part_004_surface_shell_004.stl" scale="0.001 0.001 0.001" />
      </geometry>
    </collision>
    <collision>
      <origin xyz="-0.22962916 0 0.54062108" rpy="1.5707963 0 0" />
      <geometry>
        <mesh filename="meshes/part_006_surface_shell_006.stl" scale="0.001 0.001 0.001" />
      </geometry>
    </collision>
  </link>
  <link name="arm_link2">
    <inertial>
      <origin xyz="-0.017904992 0 0.26175646" rpy="0 0 0" />
      <mass value="20.874301" />
      <inertia ixx="2.082008" iyy="2.0922838" izz="0.10286815" ixy="0" ixz="-0.041580004" iyz="0" />
    </inertial>
    <visual>
      <origin xyz="-0.026657723 0 0.52579252" rpy="1.5707963 0 0" />
      <geometry>
        <mesh filename="meshes/part_009_surface_shell_009.stl" scale="0.001 0.001 0.001" />
      </geometry>
    </visual>
    <visual>
      <origin xyz="-0.026657723 0 0.52579252" rpy="1.5707963 0 0" />
      <geometry>
        <mesh filename="meshes/part_007_surface_shell_007.stl" scale="0.001 0.001 0.001" />
      </geometry>
    </visual>
    <visual>
      <origin xyz="-0.026657723 0 0.52579252" rpy="1.5707963 0 0" />
      <geometry>
        <mesh filename="meshes/part_012_surface_shell_012.stl" scale="0.001 0.001 0.001" />
      </geometry>
    </visual>
    <visual>
      <origin xyz="-0.026657723 0 0.52579252" rpy="1.5707963 0 0" />
      <geometry>
        <mesh filename="meshes/part_008_surface_shell_008.stl" scale="0.001 0.001 0.001" />
      </geometry>
    </visual>
    <visual>
      <origin xyz="-0.026657723 0 0.52579252" rpy="1.5707963 0 0" />
      <geometry>
        <mesh filename="meshes/part_010_surface_shell_010.stl" scale="0.001 0.001 0.001" />
      </geometry>
    </visual>
    <visual>
      <origin xyz="-0.026657723 0 0.52579252" rpy="1.5707963 0 0" />
      <geometry>
        <mesh filename="meshes/part_013_surface_shell_013.stl" scale="0.001 0.001 0.001" />
      </geometry>
    </visual>
    <visual>
      <origin xyz="-0.026657723 0 0.52579252" rpy="1.5707963 0 0" />
      <geometry>
        <mesh filename="meshes/part_014_surface_shell_014.stl" scale="0.001 0.001 0.001" />
      </geometry>
    </visual>
    <collision>
      <origin xyz="-0.026657723 0 0.52579252" rpy="1.5707963 0 0" />
      <geometry>
        <mesh filename="meshes/part_009_surface_shell_009.stl" scale="0.001 0.001 0.001" />
      </geometry>
    </collision>
    <collision>
      <origin xyz="-0.026657723 0 0.52579252" rpy="1.5707963 0 0" />
      <geometry>
        <mesh filename="meshes/part_007_surface_shell_007.stl" scale="0.001 0.001 0.001" />
      </geometry>
    </collision>
    <collision>
      <origin xyz="-0.026657723 0 0.52579252" rpy="1.5707963 0 0" />
      <geometry>
        <mesh filename="meshes/part_012_surface_shell_012.stl" scale="0.001 0.001 0.001" />
      </geometry>
    </collision>
    <collision>
      <origin xyz="-0.026657723 0 0.52579252" rpy="1.5707963 0 0" />
      <geometry>
        <mesh filename="meshes/part_008_surface_shell_008.stl" scale="0.001 0.001 0.001" />
      </geometry>
    </collision>
    <collision>
      <origin xyz="-0.026657723 0 0.52579252" rpy="1.5707963 0 0" />
      <geometry>
        <mesh filename="meshes/part_010_surface_shell_010.stl" scale="0.001 0.001 0.001" />
      </geometry>
    </collision>
    <collision>
      <origin xyz="-0.026657723 0 0.52579252" rpy="1.5707963 0 0" />
      <geometry>
        <mesh filename="meshes/part_013_surface_shell_013.stl" scale="0.001 0.001 0.001" />
      </geometry>
    </collision>
    <collision>
      <origin xyz="-0.026657723 0 0.52579252" rpy="1.5707963 0 0" />
      <geometry>
        <mesh filename="meshes/part_014_surface_shell_014.stl" scale="0.001 0.001 0.001" />
      </geometry>
    </collision>
  </link>
  <link name="arm_link3">
    <inertial>
      <origin xyz="0.07704222 1.0111868e-05 0.42937999" rpy="0 0 0" />
      <mass value="14.397109" />
      <inertia ixx="1.3241009" iyy="1.3250124" izz="0.033337695" ixy="8.38828e-07" ixz="-0.01468066" iyz="5.7754159e-05" />
    </inertial>
    <visual>
      <origin xyz="-0.11682916 -1.0832491e-07 -0.35170773" rpy="1.5707963 0 0" />
      <geometry>
        <mesh filename="meshes/part_018_surface_shell_018.stl" scale="0.001 0.001 0.001" />
      </geometry>
    </visual>
    <visual>
      <origin xyz="-0.11682916 -1.0832491e-07 -0.35170773" rpy="1.5707963 0 0" />
      <geometry>
        <mesh filename="meshes/part_019_surface_shell_019.stl" scale="0.001 0.001 0.001" />
      </geometry>
    </visual>
    <visual>
      <origin xyz="-0.11682916 -1.0832491e-07 -0.35170773" rpy="1.5707963 0 0" />
      <geometry>
        <mesh filename="meshes/part_016_surface_shell_016.stl" scale="0.001 0.001 0.001" />
      </geometry>
    </visual>
    <visual>
      <origin xyz="-0.11682916 -1.0832491e-07 -0.35170773" rpy="1.5707963 0 0" />
      <geometry>
        <mesh filename="meshes/part_017_surface_shell_017.stl" scale="0.001 0.001 0.001" />
      </geometry>
    </visual>
    <collision>
      <origin xyz="-0.11682916 -1.0832491e-07 -0.35170773" rpy="1.5707963 0 0" />
      <geometry>
        <mesh filename="meshes/part_018_surface_shell_018.stl" scale="0.001 0.001 0.001" />
      </geometry>
    </collision>
    <collision>
      <origin xyz="-0.11682916 -1.0832491e-07 -0.35170773" rpy="1.5707963 0 0" />
      <geometry>
        <mesh filename="meshes/part_019_surface_shell_019.stl" scale="0.001 0.001 0.001" />
      </geometry>
    </collision>
    <collision>
      <origin xyz="-0.11682916 -1.0832491e-07 -0.35170773" rpy="1.5707963 0 0" />
      <geometry>
        <mesh filename="meshes/part_016_surface_shell_016.stl" scale="0.001 0.001 0.001" />
      </geometry>
    </collision>
    <collision>
      <origin xyz="-0.11682916 -1.0832491e-07 -0.35170773" rpy="1.5707963 0 0" />
      <geometry>
        <mesh filename="meshes/part_017_surface_shell_017.stl" scale="0.001 0.001 0.001" />
      </geometry>
    </collision>
  </link>
  <link name="arm_link4">
    <inertial>
      <origin xyz="-0.063238768 -2.1242218e-06 -0.047326444" rpy="0 0 0" />
      <mass value="3.0653792" />
      <inertia ixx="0.0041316008" iyy="0.0041484905" izz="0.0059464397" ixy="-1.0126147e-09" ixz="-2.3014681e-05" iyz="-5.7180668e-09" />
    </inertial>
    <visual>
      <origin xyz="-0.12382916 0 -1.1397075" rpy="1.5707963 0 0" />
      <geometry>
        <mesh filename="meshes/part_020_surface_shell_020.stl" scale="0.001 0.001 0.001" />
      </geometry>
    </visual>
    <visual>
      <origin xyz="-0.12382916 0 -1.1397075" rpy="1.5707963 0 0" />
      <geometry>
        <mesh filename="meshes/part_021_surface_shell_021.stl" scale="0.001 0.001 0.001" />
      </geometry>
    </visual>
    <collision>
      <origin xyz="-0.12382916 0 -1.1397075" rpy="1.5707963 0 0" />
      <geometry>
        <mesh filename="meshes/part_020_surface_shell_020.stl" scale="0.001 0.001 0.001" />
      </geometry>
    </collision>
    <collision>
      <origin xyz="-0.12382916 0 -1.1397075" rpy="1.5707963 0 0" />
      <geometry>
        <mesh filename="meshes/part_021_surface_shell_021.stl" scale="0.001 0.001 0.001" />
      </geometry>
    </collision>
  </link>
  <link name="arm_link5">
    <inertial>
      <origin xyz="0.046931114 2.1069891e-06 0.12226889" rpy="0 0 0" />
      <mass value="2.0898922" />
      <inertia ixx="0.0040576491" iyy="0.0028894583" izz="0.0028711567" ixy="-5.7000627e-09" ixz="-2.2942243e-05" iyz="-1.0094288e-09" />
    </inertial>
    <visual>
      <origin xyz="-0.060329165 0 -1.1516074" rpy="1.5707963 0 0" />
      <geometry>
        <mesh filename="meshes/part_022_surface_shell_022.stl" scale="0.001 0.001 0.001" />
      </geometry>
    </visual>
    <visual>
      <origin xyz="-0.060329165 0 -1.1516074" rpy="1.5707963 0 0" />
      <geometry>
        <mesh filename="meshes/part_023_surface_shell_023.stl" scale="0.001 0.001 0.001" />
      </geometry>
    </visual>
    <collision>
      <origin xyz="-0.060329165 0 -1.1516074" rpy="1.5707963 0 0" />
      <geometry>
        <mesh filename="meshes/part_022_surface_shell_022.stl" scale="0.001 0.001 0.001" />
      </geometry>
    </collision>
    <collision>
      <origin xyz="-0.060329165 0 -1.1516074" rpy="1.5707963 0 0" />
      <geometry>
        <mesh filename="meshes/part_023_surface_shell_023.stl" scale="0.001 0.001 0.001" />
      </geometry>
    </collision>
  </link>
  <link name="arm_link6">
    <inertial>
      <origin xyz="-0.018227671 -0.013915083 -0.0052569311" rpy="0 0 0" />
      <mass value="0.17086269" />
      <inertia ixx="0.00035244747" iyy="0.00023340002" izz="0.0001503043" ixy="-1.4321609e-05" ixz="-5.3331186e-06" iyz="7.2255633e-05" />
    </inertial>
    <visual>
      <origin xyz="0.0039208355 0 -1.2742075" rpy="1.5707963 0 0" />
      <geometry>
        <mesh filename="meshes/part_025_surface_shell_025.stl" scale="0.001 0.001 0.001" />
      </geometry>
    </visual>
    <visual>
      <origin xyz="0.0039208355 0 -1.2742075" rpy="1.5707963 0 0" />
      <geometry>
        <mesh filename="meshes/part_035_surface_shell_035.stl" scale="0.001 0.001 0.001" />
      </geometry>
    </visual>
    <visual>
      <origin xyz="0.0039208355 0 -1.2742075" rpy="1.5707963 0 0" />
      <geometry>
        <mesh filename="meshes/part_032_surface_shell_032.stl" scale="0.001 0.001 0.001" />
      </geometry>
    </visual>
    <visual>
      <origin xyz="0.0039208355 0 -1.2742075" rpy="1.5707963 0 0" />
      <geometry>
        <mesh filename="meshes/part_042_surface_shell_042.stl" scale="0.001 0.001 0.001" />
      </geometry>
    </visual>
    <collision>
      <origin xyz="0.0039208355 0 -1.2742075" rpy="1.5707963 0 0" />
      <geometry>
        <mesh filename="meshes/part_025_surface_shell_025.stl" scale="0.001 0.001 0.001" />
      </geometry>
    </collision>
    <collision>
      <origin xyz="0.0039208355 0 -1.2742075" rpy="1.5707963 0 0" />
      <geometry>
        <mesh filename="meshes/part_035_surface_shell_035.stl" scale="0.001 0.001 0.001" />
      </geometry>
    </collision>
    <collision>
      <origin xyz="0.0039208355 0 -1.2742075" rpy="1.5707963 0 0" />
      <geometry>
        <mesh filename="meshes/part_032_surface_shell_032.stl" scale="0.001 0.001 0.001" />
      </geometry>
    </collision>
    <collision>
      <origin xyz="0.0039208355 0 -1.2742075" rpy="1.5707963 0 0" />
      <geometry>
        <mesh filename="meshes/part_042_surface_shell_042.stl" scale="0.001 0.001 0.001" />
      </geometry>
    </collision>
  </link>
  <link name="hooker_link">
    <inertial>
      <origin xyz="-0.148398 0.0047145063 1.2751437" rpy="0 0 0" />
      <mass value="1.0086852" />
      <inertia ixx="0.0027117321" iyy="0.0049346773" izz="0.0049529325" ixy="0.00040310469" ixz="3.0415636e-05" iyz="-0.00010145148" />
    </inertial>
    <visual>
      <origin xyz="0 0 0" rpy="1.5707963 0 0" />
      <geometry>
        <mesh filename="meshes/part_093_solid_093.stl" scale="0.001 0.001 0.001" />
      </geometry>
    </visual>
    <visual>
      <origin xyz="0 0 0" rpy="1.5707963 0 0" />
      <geometry>
        <mesh filename="meshes/part_087_solid_087.stl" scale="0.001 0.001 0.001" />
      </geometry>
    </visual>
    <visual>
      <origin xyz="0 0 0" rpy="1.5707963 0 0" />
      <geometry>
        <mesh filename="meshes/part_091_solid_091.stl" scale="0.001 0.001 0.001" />
      </geometry>
    </visual>
    <visual>
      <origin xyz="0 0 0" rpy="1.5707963 0 0" />
      <geometry>
        <mesh filename="meshes/part_078_solid_078.stl" scale="0.001 0.001 0.001" />
      </geometry>
    </visual>
    <visual>
      <origin xyz="0 0 0" rpy="1.5707963 0 0" />
      <geometry>
        <mesh filename="meshes/part_081_solid_081.stl" scale="0.001 0.001 0.001" />
      </geometry>
    </visual>
    <visual>
      <origin xyz="0 0 0" rpy="1.5707963 0 0" />
      <geometry>
        <mesh filename="meshes/part_097_solid_097.stl" scale="0.001 0.001 0.001" />
      </geometry>
    </visual>
    <visual>
      <origin xyz="0 0 0" rpy="1.5707963 0 0" />
      <geometry>
        <mesh filename="meshes/part_085_solid_085.stl" scale="0.001 0.001 0.001" />
      </geometry>
    </visual>
    <visual>
      <origin xyz="0 0 0" rpy="1.5707963 0 0" />
      <geometry>
        <mesh filename="meshes/part_076_solid_076.stl" scale="0.001 0.001 0.001" />
      </geometry>
    </visual>
    <visual>
      <origin xyz="0 0 0" rpy="1.5707963 0 0" />
      <geometry>
        <mesh filename="meshes/part_094_solid_094.stl" scale="0.001 0.001 0.001" />
      </geometry>
    </visual>
    <visual>
      <origin xyz="0 0 0" rpy="1.5707963 0 0" />
      <geometry>
        <mesh filename="meshes/part_119_solid_119.stl" scale="0.001 0.001 0.001" />
      </geometry>
    </visual>
    <visual>
      <origin xyz="0 0 0" rpy="1.5707963 0 0" />
      <geometry>
        <mesh filename="meshes/part_124_solid_124.stl" scale="0.001 0.001 0.001" />
      </geometry>
    </visual>
    <visual>
      <origin xyz="0 0 0" rpy="1.5707963 0 0" />
      <geometry>
        <mesh filename="meshes/part_024_surface_shell_024.stl" scale="0.001 0.001 0.001" />
      </geometry>
    </visual>
    <visual>
      <origin xyz="0 0 0" rpy="1.5707963 0 0" />
      <geometry>
        <mesh filename="meshes/part_043_solid_043.stl" scale="0.001 0.001 0.001" />
      </geometry>
    </visual>
    <visual>
      <origin xyz="0 0 0" rpy="1.5707963 0 0" />
      <geometry>
        <mesh filename="meshes/part_044_solid_044.stl" scale="0.001 0.001 0.001" />
      </geometry>
    </visual>
    <visual>
      <origin xyz="0 0 0" rpy="1.5707963 0 0" />
      <geometry>
        <mesh filename="meshes/part_045_solid_045.stl" scale="0.001 0.001 0.001" />
      </geometry>
    </visual>
    <visual>
      <origin xyz="0 0 0" rpy="1.5707963 0 0" />
      <geometry>
        <mesh filename="meshes/part_046_solid_046.stl" scale="0.001 0.001 0.001" />
      </geometry>
    </visual>
    <visual>
      <origin xyz="0 0 0" rpy="1.5707963 0 0" />
      <geometry>
        <mesh filename="meshes/part_047_solid_047.stl" scale="0.001 0.001 0.001" />
      </geometry>
    </visual>
    <visual>
      <origin xyz="0 0 0" rpy="1.5707963 0 0" />
      <geometry>
        <mesh filename="meshes/part_048_solid_048.stl" scale="0.001 0.001 0.001" />
      </geometry>
    </visual>
    <visual>
      <origin xyz="0 0 0" rpy="1.5707963 0 0" />
      <geometry>
        <mesh filename="meshes/part_049_solid_049.stl" scale="0.001 0.001 0.001" />
      </geometry>
    </visual>
    <visual>
      <origin xyz="0 0 0" rpy="1.5707963 0 0" />
      <geometry>
        <mesh filename="meshes/part_050_solid_050.stl" scale="0.001 0.001 0.001" />
      </geometry>
    </visual>
    <visual>
      <origin xyz="0 0 0" rpy="1.5707963 0 0" />
      <geometry>
        <mesh filename="meshes/part_051_solid_051.stl" scale="0.001 0.001 0.001" />
      </geometry>
    </visual>
    <visual>
      <origin xyz="0 0 0" rpy="1.5707963 0 0" />
      <geometry>
        <mesh filename="meshes/part_052_solid_052.stl" scale="0.001 0.001 0.001" />
      </geometry>
    </visual>
    <visual>
      <origin xyz="0 0 0" rpy="1.5707963 0 0" />
      <geometry>
        <mesh filename="meshes/part_053_solid_053.stl" scale="0.001 0.001 0.001" />
      </geometry>
    </visual>
    <visual>
      <origin xyz="0 0 0" rpy="1.5707963 0 0" />
      <geometry>
        <mesh filename="meshes/part_054_solid_054.stl" scale="0.001 0.001 0.001" />
      </geometry>
    </visual>
    <visual>
      <origin xyz="0 0 0" rpy="1.5707963 0 0" />
      <geometry>
        <mesh filename="meshes/part_055_solid_055.stl" scale="0.001 0.001 0.001" />
      </geometry>
    </visual>
    <visual>
      <origin xyz="0 0 0" rpy="1.5707963 0 0" />
      <geometry>
        <mesh filename="meshes/part_056_solid_056.stl" scale="0.001 0.001 0.001" />
      </geometry>
    </visual>
    <visual>
      <origin xyz="0 0 0" rpy="1.5707963 0 0" />
      <geometry>
        <mesh filename="meshes/part_057_solid_057.stl" scale="0.001 0.001 0.001" />
      </geometry>
    </visual>
    <visual>
      <origin xyz="0 0 0" rpy="1.5707963 0 0" />
      <geometry>
        <mesh filename="meshes/part_058_solid_058.stl" scale="0.001 0.001 0.001" />
      </geometry>
    </visual>
    <visual>
      <origin xyz="0 0 0" rpy="1.5707963 0 0" />
      <geometry>
        <mesh filename="meshes/part_059_solid_059.stl" scale="0.001 0.001 0.001" />
      </geometry>
    </visual>
    <visual>
      <origin xyz="0 0 0" rpy="1.5707963 0 0" />
      <geometry>
        <mesh filename="meshes/part_060_solid_060.stl" scale="0.001 0.001 0.001" />
      </geometry>
    </visual>
    <visual>
      <origin xyz="0 0 0" rpy="1.5707963 0 0" />
      <geometry>
        <mesh filename="meshes/part_061_solid_061.stl" scale="0.001 0.001 0.001" />
      </geometry>
    </visual>
    <visual>
      <origin xyz="0 0 0" rpy="1.5707963 0 0" />
      <geometry>
        <mesh filename="meshes/part_062_solid_062.stl" scale="0.001 0.001 0.001" />
      </geometry>
    </visual>
    <visual>
      <origin xyz="0 0 0" rpy="1.5707963 0 0" />
      <geometry>
        <mesh filename="meshes/part_063_solid_063.stl" scale="0.001 0.001 0.001" />
      </geometry>
    </visual>
    <visual>
      <origin xyz="0 0 0" rpy="1.5707963 0 0" />
      <geometry>
        <mesh filename="meshes/part_064_solid_064.stl" scale="0.001 0.001 0.001" />
      </geometry>
    </visual>
    <visual>
      <origin xyz="0 0 0" rpy="1.5707963 0 0" />
      <geometry>
        <mesh filename="meshes/part_065_solid_065.stl" scale="0.001 0.001 0.001" />
      </geometry>
    </visual>
    <visual>
      <origin xyz="0 0 0" rpy="1.5707963 0 0" />
      <geometry>
        <mesh filename="meshes/part_066_solid_066.stl" scale="0.001 0.001 0.001" />
      </geometry>
    </visual>
    <visual>
      <origin xyz="0 0 0" rpy="1.5707963 0 0" />
      <geometry>
        <mesh filename="meshes/part_067_solid_067.stl" scale="0.001 0.001 0.001" />
      </geometry>
    </visual>
    <visual>
      <origin xyz="0 0 0" rpy="1.5707963 0 0" />
      <geometry>
        <mesh filename="meshes/part_068_solid_068.stl" scale="0.001 0.001 0.001" />
      </geometry>
    </visual>
    <visual>
      <origin xyz="0 0 0" rpy="1.5707963 0 0" />
      <geometry>
        <mesh filename="meshes/part_069_solid_069.stl" scale="0.001 0.001 0.001" />
      </geometry>
    </visual>
    <visual>
      <origin xyz="0 0 0" rpy="1.5707963 0 0" />
      <geometry>
        <mesh filename="meshes/part_070_solid_070.stl" scale="0.001 0.001 0.001" />
      </geometry>
    </visual>
    <visual>
      <origin xyz="0 0 0" rpy="1.5707963 0 0" />
      <geometry>
        <mesh filename="meshes/part_071_solid_071.stl" scale="0.001 0.001 0.001" />
      </geometry>
    </visual>
    <visual>
      <origin xyz="0 0 0" rpy="1.5707963 0 0" />
      <geometry>
        <mesh filename="meshes/part_072_solid_072.stl" scale="0.001 0.001 0.001" />
      </geometry>
    </visual>
    <visual>
      <origin xyz="0 0 0" rpy="1.5707963 0 0" />
      <geometry>
        <mesh filename="meshes/part_073_solid_073.stl" scale="0.001 0.001 0.001" />
      </geometry>
    </visual>
    <visual>
      <origin xyz="0 0 0" rpy="1.5707963 0 0" />
      <geometry>
        <mesh filename="meshes/part_074_solid_074.stl" scale="0.001 0.001 0.001" />
      </geometry>
    </visual>
    <visual>
      <origin xyz="0 0 0" rpy="1.5707963 0 0" />
      <geometry>
        <mesh filename="meshes/part_075_solid_075.stl" scale="0.001 0.001 0.001" />
      </geometry>
    </visual>
    <visual>
      <origin xyz="0 0 0" rpy="1.5707963 0 0" />
      <geometry>
        <mesh filename="meshes/part_077_solid_077.stl" scale="0.001 0.001 0.001" />
      </geometry>
    </visual>
    <visual>
      <origin xyz="0 0 0" rpy="1.5707963 0 0" />
      <geometry>
        <mesh filename="meshes/part_079_solid_079.stl" scale="0.001 0.001 0.001" />
      </geometry>
    </visual>
    <visual>
      <origin xyz="0 0 0" rpy="1.5707963 0 0" />
      <geometry>
        <mesh filename="meshes/part_080_solid_080.stl" scale="0.001 0.001 0.001" />
      </geometry>
    </visual>
    <visual>
      <origin xyz="0 0 0" rpy="1.5707963 0 0" />
      <geometry>
        <mesh filename="meshes/part_082_solid_082.stl" scale="0.001 0.001 0.001" />
      </geometry>
    </visual>
    <visual>
      <origin xyz="0 0 0" rpy="1.5707963 0 0" />
      <geometry>
        <mesh filename="meshes/part_084_solid_084.stl" scale="0.001 0.001 0.001" />
      </geometry>
    </visual>
    <visual>
      <origin xyz="0 0 0" rpy="1.5707963 0 0" />
      <geometry>
        <mesh filename="meshes/part_086_solid_086.stl" scale="0.001 0.001 0.001" />
      </geometry>
    </visual>
    <visual>
      <origin xyz="0 0 0" rpy="1.5707963 0 0" />
      <geometry>
        <mesh filename="meshes/part_088_solid_088.stl" scale="0.001 0.001 0.001" />
      </geometry>
    </visual>
    <visual>
      <origin xyz="0 0 0" rpy="1.5707963 0 0" />
      <geometry>
        <mesh filename="meshes/part_089_solid_089.stl" scale="0.001 0.001 0.001" />
      </geometry>
    </visual>
    <visual>
      <origin xyz="0 0 0" rpy="1.5707963 0 0" />
      <geometry>
        <mesh filename="meshes/part_090_solid_090.stl" scale="0.001 0.001 0.001" />
      </geometry>
    </visual>
    <visual>
      <origin xyz="0 0 0" rpy="1.5707963 0 0" />
      <geometry>
        <mesh filename="meshes/part_092_solid_092.stl" scale="0.001 0.001 0.001" />
      </geometry>
    </visual>
    <visual>
      <origin xyz="0 0 0" rpy="1.5707963 0 0" />
      <geometry>
        <mesh filename="meshes/part_095_solid_095.stl" scale="0.001 0.001 0.001" />
      </geometry>
    </visual>
    <visual>
      <origin xyz="0 0 0" rpy="1.5707963 0 0" />
      <geometry>
        <mesh filename="meshes/part_096_solid_096.stl" scale="0.001 0.001 0.001" />
      </geometry>
    </visual>
    <visual>
      <origin xyz="0 0 0" rpy="1.5707963 0 0" />
      <geometry>
        <mesh filename="meshes/part_098_solid_098.stl" scale="0.001 0.001 0.001" />
      </geometry>
    </visual>
    <visual>
      <origin xyz="0 0 0" rpy="1.5707963 0 0" />
      <geometry>
        <mesh filename="meshes/part_101_solid_101.stl" scale="0.001 0.001 0.001" />
      </geometry>
    </visual>
    <visual>
      <origin xyz="0 0 0" rpy="1.5707963 0 0" />
      <geometry>
        <mesh filename="meshes/part_102_solid_102.stl" scale="0.001 0.001 0.001" />
      </geometry>
    </visual>
    <visual>
      <origin xyz="0 0 0" rpy="1.5707963 0 0" />
      <geometry>
        <mesh filename="meshes/part_103_solid_103.stl" scale="0.001 0.001 0.001" />
      </geometry>
    </visual>
    <visual>
      <origin xyz="0 0 0" rpy="1.5707963 0 0" />
      <geometry>
        <mesh filename="meshes/part_104_solid_104.stl" scale="0.001 0.001 0.001" />
      </geometry>
    </visual>
    <visual>
      <origin xyz="0 0 0" rpy="1.5707963 0 0" />
      <geometry>
        <mesh filename="meshes/part_105_solid_105.stl" scale="0.001 0.001 0.001" />
      </geometry>
    </visual>
    <visual>
      <origin xyz="0 0 0" rpy="1.5707963 0 0" />
      <geometry>
        <mesh filename="meshes/part_106_solid_106.stl" scale="0.001 0.001 0.001" />
      </geometry>
    </visual>
    <visual>
      <origin xyz="0 0 0" rpy="1.5707963 0 0" />
      <geometry>
        <mesh filename="meshes/part_107_solid_107.stl" scale="0.001 0.001 0.001" />
      </geometry>
    </visual>
    <visual>
      <origin xyz="0 0 0" rpy="1.5707963 0 0" />
      <geometry>
        <mesh filename="meshes/part_108_solid_108.stl" scale="0.001 0.001 0.001" />
      </geometry>
    </visual>
    <visual>
      <origin xyz="0 0 0" rpy="1.5707963 0 0" />
      <geometry>
        <mesh filename="meshes/part_109_solid_109.stl" scale="0.001 0.001 0.001" />
      </geometry>
    </visual>
    <visual>
      <origin xyz="0 0 0" rpy="1.5707963 0 0" />
      <geometry>
        <mesh filename="meshes/part_110_solid_110.stl" scale="0.001 0.001 0.001" />
      </geometry>
    </visual>
    <visual>
      <origin xyz="0 0 0" rpy="1.5707963 0 0" />
      <geometry>
        <mesh filename="meshes/part_111_solid_111.stl" scale="0.001 0.001 0.001" />
      </geometry>
    </visual>
    <visual>
      <origin xyz="0 0 0" rpy="1.5707963 0 0" />
      <geometry>
        <mesh filename="meshes/part_112_solid_112.stl" scale="0.001 0.001 0.001" />
      </geometry>
    </visual>
    <visual>
      <origin xyz="0 0 0" rpy="1.5707963 0 0" />
      <geometry>
        <mesh filename="meshes/part_113_solid_113.stl" scale="0.001 0.001 0.001" />
      </geometry>
    </visual>
    <visual>
      <origin xyz="0 0 0" rpy="1.5707963 0 0" />
      <geometry>
        <mesh filename="meshes/part_114_solid_114.stl" scale="0.001 0.001 0.001" />
      </geometry>
    </visual>
    <visual>
      <origin xyz="0 0 0" rpy="1.5707963 0 0" />
      <geometry>
        <mesh filename="meshes/part_115_solid_115.stl" scale="0.001 0.001 0.001" />
      </geometry>
    </visual>
    <visual>
      <origin xyz="0 0 0" rpy="1.5707963 0 0" />
      <geometry>
        <mesh filename="meshes/part_116_solid_116.stl" scale="0.001 0.001 0.001" />
      </geometry>
    </visual>
    <visual>
      <origin xyz="0 0 0" rpy="1.5707963 0 0" />
      <geometry>
        <mesh filename="meshes/part_117_solid_117.stl" scale="0.001 0.001 0.001" />
      </geometry>
    </visual>
    <visual>
      <origin xyz="0 0 0" rpy="1.5707963 0 0" />
      <geometry>
        <mesh filename="meshes/part_118_solid_118.stl" scale="0.001 0.001 0.001" />
      </geometry>
    </visual>
    <visual>
      <origin xyz="0 0 0" rpy="1.5707963 0 0" />
      <geometry>
        <mesh filename="meshes/part_120_solid_120.stl" scale="0.001 0.001 0.001" />
      </geometry>
    </visual>
    <visual>
      <origin xyz="0 0 0" rpy="1.5707963 0 0" />
      <geometry>
        <mesh filename="meshes/part_121_solid_121.stl" scale="0.001 0.001 0.001" />
      </geometry>
    </visual>
    <visual>
      <origin xyz="0 0 0" rpy="1.5707963 0 0" />
      <geometry>
        <mesh filename="meshes/part_122_solid_122.stl" scale="0.001 0.001 0.001" />
      </geometry>
    </visual>
    <visual>
      <origin xyz="0 0 0" rpy="1.5707963 0 0" />
      <geometry>
        <mesh filename="meshes/part_123_solid_123.stl" scale="0.001 0.001 0.001" />
      </geometry>
    </visual>
    <visual>
      <origin xyz="0 0 0" rpy="1.5707963 0 0" />
      <geometry>
        <mesh filename="meshes/part_125_solid_125.stl" scale="0.001 0.001 0.001" />
      </geometry>
    </visual>
    <collision>
      <origin xyz="0 0 0" rpy="1.5707963 0 0" />
      <geometry>
        <mesh filename="meshes/part_093_solid_093.stl" scale="0.001 0.001 0.001" />
      </geometry>
    </collision>
    <collision>
      <origin xyz="0 0 0" rpy="1.5707963 0 0" />
      <geometry>
        <mesh filename="meshes/part_087_solid_087.stl" scale="0.001 0.001 0.001" />
      </geometry>
    </collision>
    <collision>
      <origin xyz="0 0 0" rpy="1.5707963 0 0" />
      <geometry>
        <mesh filename="meshes/part_091_solid_091.stl" scale="0.001 0.001 0.001" />
      </geometry>
    </collision>
    <collision>
      <origin xyz="0 0 0" rpy="1.5707963 0 0" />
      <geometry>
        <mesh filename="meshes/part_078_solid_078.stl" scale="0.001 0.001 0.001" />
      </geometry>
    </collision>
    <collision>
      <origin xyz="0 0 0" rpy="1.5707963 0 0" />
      <geometry>
        <mesh filename="meshes/part_081_solid_081.stl" scale="0.001 0.001 0.001" />
      </geometry>
    </collision>
    <collision>
      <origin xyz="0 0 0" rpy="1.5707963 0 0" />
      <geometry>
        <mesh filename="meshes/part_097_solid_097.stl" scale="0.001 0.001 0.001" />
      </geometry>
    </collision>
    <collision>
      <origin xyz="0 0 0" rpy="1.5707963 0 0" />
      <geometry>
        <mesh filename="meshes/part_085_solid_085.stl" scale="0.001 0.001 0.001" />
      </geometry>
    </collision>
    <collision>
      <origin xyz="0 0 0" rpy="1.5707963 0 0" />
      <geometry>
        <mesh filename="meshes/part_076_solid_076.stl" scale="0.001 0.001 0.001" />
      </geometry>
    </collision>
    <collision>
      <origin xyz="0 0 0" rpy="1.5707963 0 0" />
      <geometry>
        <mesh filename="meshes/part_094_solid_094.stl" scale="0.001 0.001 0.001" />
      </geometry>
    </collision>
    <collision>
      <origin xyz="0 0 0" rpy="1.5707963 0 0" />
      <geometry>
        <mesh filename="meshes/part_119_solid_119.stl" scale="0.001 0.001 0.001" />
      </geometry>
    </collision>
    <collision>
      <origin xyz="0 0 0" rpy="1.5707963 0 0" />
      <geometry>
        <mesh filename="meshes/part_124_solid_124.stl" scale="0.001 0.001 0.001" />
      </geometry>
    </collision>
    <collision>
      <origin xyz="0 0 0" rpy="1.5707963 0 0" />
      <geometry>
        <mesh filename="meshes/part_024_surface_shell_024.stl" scale="0.001 0.001 0.001" />
      </geometry>
    </collision>
    <collision>
      <origin xyz="0 0 0" rpy="1.5707963 0 0" />
      <geometry>
        <mesh filename="meshes/part_043_solid_043.stl" scale="0.001 0.001 0.001" />
      </geometry>
    </collision>
    <collision>
      <origin xyz="0 0 0" rpy="1.5707963 0 0" />
      <geometry>
        <mesh filename="meshes/part_044_solid_044.stl" scale="0.001 0.001 0.001" />
      </geometry>
    </collision>
    <collision>
      <origin xyz="0 0 0" rpy="1.5707963 0 0" />
      <geometry>
        <mesh filename="meshes/part_045_solid_045.stl" scale="0.001 0.001 0.001" />
      </geometry>
    </collision>
    <collision>
      <origin xyz="0 0 0" rpy="1.5707963 0 0" />
      <geometry>
        <mesh filename="meshes/part_046_solid_046.stl" scale="0.001 0.001 0.001" />
      </geometry>
    </collision>
    <collision>
      <origin xyz="0 0 0" rpy="1.5707963 0 0" />
      <geometry>
        <mesh filename="meshes/part_047_solid_047.stl" scale="0.001 0.001 0.001" />
      </geometry>
    </collision>
    <collision>
      <origin xyz="0 0 0" rpy="1.5707963 0 0" />
      <geometry>
        <mesh filename="meshes/part_048_solid_048.stl" scale="0.001 0.001 0.001" />
      </geometry>
    </collision>
    <collision>
      <origin xyz="0 0 0" rpy="1.5707963 0 0" />
      <geometry>
        <mesh filename="meshes/part_049_solid_049.stl" scale="0.001 0.001 0.001" />
      </geometry>
    </collision>
    <collision>
      <origin xyz="0 0 0" rpy="1.5707963 0 0" />
      <geometry>
        <mesh filename="meshes/part_050_solid_050.stl" scale="0.001 0.001 0.001" />
      </geometry>
    </collision>
    <collision>
      <origin xyz="0 0 0" rpy="1.5707963 0 0" />
      <geometry>
        <mesh filename="meshes/part_051_solid_051.stl" scale="0.001 0.001 0.001" />
      </geometry>
    </collision>
    <collision>
      <origin xyz="0 0 0" rpy="1.5707963 0 0" />
      <geometry>
        <mesh filename="meshes/part_052_solid_052.stl" scale="0.001 0.001 0.001" />
      </geometry>
    </collision>
    <collision>
      <origin xyz="0 0 0" rpy="1.5707963 0 0" />
      <geometry>
        <mesh filename="meshes/part_053_solid_053.stl" scale="0.001 0.001 0.001" />
      </geometry>
    </collision>
    <collision>
      <origin xyz="0 0 0" rpy="1.5707963 0 0" />
      <geometry>
        <mesh filename="meshes/part_054_solid_054.stl" scale="0.001 0.001 0.001" />
      </geometry>
    </collision>
    <collision>
      <origin xyz="0 0 0" rpy="1.5707963 0 0" />
      <geometry>
        <mesh filename="meshes/part_055_solid_055.stl" scale="0.001 0.001 0.001" />
      </geometry>
    </collision>
    <collision>
      <origin xyz="0 0 0" rpy="1.5707963 0 0" />
      <geometry>
        <mesh filename="meshes/part_056_solid_056.stl" scale="0.001 0.001 0.001" />
      </geometry>
    </collision>
    <collision>
      <origin xyz="0 0 0" rpy="1.5707963 0 0" />
      <geometry>
        <mesh filename="meshes/part_057_solid_057.stl" scale="0.001 0.001 0.001" />
      </geometry>
    </collision>
    <collision>
      <origin xyz="0 0 0" rpy="1.5707963 0 0" />
      <geometry>
        <mesh filename="meshes/part_058_solid_058.stl" scale="0.001 0.001 0.001" />
      </geometry>
    </collision>
    <collision>
      <origin xyz="0 0 0" rpy="1.5707963 0 0" />
      <geometry>
        <mesh filename="meshes/part_059_solid_059.stl" scale="0.001 0.001 0.001" />
      </geometry>
    </collision>
    <collision>
      <origin xyz="0 0 0" rpy="1.5707963 0 0" />
      <geometry>
        <mesh filename="meshes/part_060_solid_060.stl" scale="0.001 0.001 0.001" />
      </geometry>
    </collision>
    <collision>
      <origin xyz="0 0 0" rpy="1.5707963 0 0" />
      <geometry>
        <mesh filename="meshes/part_061_solid_061.stl" scale="0.001 0.001 0.001" />
      </geometry>
    </collision>
    <collision>
      <origin xyz="0 0 0" rpy="1.5707963 0 0" />
      <geometry>
        <mesh filename="meshes/part_062_solid_062.stl" scale="0.001 0.001 0.001" />
      </geometry>
    </collision>
    <collision>
      <origin xyz="0 0 0" rpy="1.5707963 0 0" />
      <geometry>
        <mesh filename="meshes/part_063_solid_063.stl" scale="0.001 0.001 0.001" />
      </geometry>
    </collision>
    <collision>
      <origin xyz="0 0 0" rpy="1.5707963 0 0" />
      <geometry>
        <mesh filename="meshes/part_064_solid_064.stl" scale="0.001 0.001 0.001" />
      </geometry>
    </collision>
    <collision>
      <origin xyz="0 0 0" rpy="1.5707963 0 0" />
      <geometry>
        <mesh filename="meshes/part_065_solid_065.stl" scale="0.001 0.001 0.001" />
      </geometry>
    </collision>
    <collision>
      <origin xyz="0 0 0" rpy="1.5707963 0 0" />
      <geometry>
        <mesh filename="meshes/part_066_solid_066.stl" scale="0.001 0.001 0.001" />
      </geometry>
    </collision>
    <collision>
      <origin xyz="0 0 0" rpy="1.5707963 0 0" />
      <geometry>
        <mesh filename="meshes/part_067_solid_067.stl" scale="0.001 0.001 0.001" />
      </geometry>
    </collision>
    <collision>
      <origin xyz="0 0 0" rpy="1.5707963 0 0" />
      <geometry>
        <mesh filename="meshes/part_068_solid_068.stl" scale="0.001 0.001 0.001" />
      </geometry>
    </collision>
    <collision>
      <origin xyz="0 0 0" rpy="1.5707963 0 0" />
      <geometry>
        <mesh filename="meshes/part_069_solid_069.stl" scale="0.001 0.001 0.001" />
      </geometry>
    </collision>
    <collision>
      <origin xyz="0 0 0" rpy="1.5707963 0 0" />
      <geometry>
        <mesh filename="meshes/part_070_solid_070.stl" scale="0.001 0.001 0.001" />
      </geometry>
    </collision>
    <collision>
      <origin xyz="0 0 0" rpy="1.5707963 0 0" />
      <geometry>
        <mesh filename="meshes/part_071_solid_071.stl" scale="0.001 0.001 0.001" />
      </geometry>
    </collision>
    <collision>
      <origin xyz="0 0 0" rpy="1.5707963 0 0" />
      <geometry>
        <mesh filename="meshes/part_072_solid_072.stl" scale="0.001 0.001 0.001" />
      </geometry>
    </collision>
    <collision>
      <origin xyz="0 0 0" rpy="1.5707963 0 0" />
      <geometry>
        <mesh filename="meshes/part_073_solid_073.stl" scale="0.001 0.001 0.001" />
      </geometry>
    </collision>
    <collision>
      <origin xyz="0 0 0" rpy="1.5707963 0 0" />
      <geometry>
        <mesh filename="meshes/part_074_solid_074.stl" scale="0.001 0.001 0.001" />
      </geometry>
    </collision>
    <collision>
      <origin xyz="0 0 0" rpy="1.5707963 0 0" />
      <geometry>
        <mesh filename="meshes/part_075_solid_075.stl" scale="0.001 0.001 0.001" />
      </geometry>
    </collision>
    <collision>
      <origin xyz="0 0 0" rpy="1.5707963 0 0" />
      <geometry>
        <mesh filename="meshes/part_077_solid_077.stl" scale="0.001 0.001 0.001" />
      </geometry>
    </collision>
    <collision>
      <origin xyz="0 0 0" rpy="1.5707963 0 0" />
      <geometry>
        <mesh filename="meshes/part_079_solid_079.stl" scale="0.001 0.001 0.001" />
      </geometry>
    </collision>
    <collision>
      <origin xyz="0 0 0" rpy="1.5707963 0 0" />
      <geometry>
        <mesh filename="meshes/part_080_solid_080.stl" scale="0.001 0.001 0.001" />
      </geometry>
    </collision>
    <collision>
      <origin xyz="0 0 0" rpy="1.5707963 0 0" />
      <geometry>
        <mesh filename="meshes/part_082_solid_082.stl" scale="0.001 0.001 0.001" />
      </geometry>
    </collision>
    <collision>
      <origin xyz="0 0 0" rpy="1.5707963 0 0" />
      <geometry>
        <mesh filename="meshes/part_084_solid_084.stl" scale="0.001 0.001 0.001" />
      </geometry>
    </collision>
    <collision>
      <origin xyz="0 0 0" rpy="1.5707963 0 0" />
      <geometry>
        <mesh filename="meshes/part_086_solid_086.stl" scale="0.001 0.001 0.001" />
      </geometry>
    </collision>
    <collision>
      <origin xyz="0 0 0" rpy="1.5707963 0 0" />
      <geometry>
        <mesh filename="meshes/part_088_solid_088.stl" scale="0.001 0.001 0.001" />
      </geometry>
    </collision>
    <collision>
      <origin xyz="0 0 0" rpy="1.5707963 0 0" />
      <geometry>
        <mesh filename="meshes/part_089_solid_089.stl" scale="0.001 0.001 0.001" />
      </geometry>
    </collision>
    <collision>
      <origin xyz="0 0 0" rpy="1.5707963 0 0" />
      <geometry>
        <mesh filename="meshes/part_090_solid_090.stl" scale="0.001 0.001 0.001" />
      </geometry>
    </collision>
    <collision>
      <origin xyz="0 0 0" rpy="1.5707963 0 0" />
      <geometry>
        <mesh filename="meshes/part_092_solid_092.stl" scale="0.001 0.001 0.001" />
      </geometry>
    </collision>
    <collision>
      <origin xyz="0 0 0" rpy="1.5707963 0 0" />
      <geometry>
        <mesh filename="meshes/part_095_solid_095.stl" scale="0.001 0.001 0.001" />
      </geometry>
    </collision>
    <collision>
      <origin xyz="0 0 0" rpy="1.5707963 0 0" />
      <geometry>
        <mesh filename="meshes/part_096_solid_096.stl" scale="0.001 0.001 0.001" />
      </geometry>
    </collision>
    <collision>
      <origin xyz="0 0 0" rpy="1.5707963 0 0" />
      <geometry>
        <mesh filename="meshes/part_098_solid_098.stl" scale="0.001 0.001 0.001" />
      </geometry>
    </collision>
    <collision>
      <origin xyz="0 0 0" rpy="1.5707963 0 0" />
      <geometry>
        <mesh filename="meshes/part_101_solid_101.stl" scale="0.001 0.001 0.001" />
      </geometry>
    </collision>
    <collision>
      <origin xyz="0 0 0" rpy="1.5707963 0 0" />
      <geometry>
        <mesh filename="meshes/part_102_solid_102.stl" scale="0.001 0.001 0.001" />
      </geometry>
    </collision>
    <collision>
      <origin xyz="0 0 0" rpy="1.5707963 0 0" />
      <geometry>
        <mesh filename="meshes/part_103_solid_103.stl" scale="0.001 0.001 0.001" />
      </geometry>
    </collision>
    <collision>
      <origin xyz="0 0 0" rpy="1.5707963 0 0" />
      <geometry>
        <mesh filename="meshes/part_104_solid_104.stl" scale="0.001 0.001 0.001" />
      </geometry>
    </collision>
    <collision>
      <origin xyz="0 0 0" rpy="1.5707963 0 0" />
      <geometry>
        <mesh filename="meshes/part_105_solid_105.stl" scale="0.001 0.001 0.001" />
      </geometry>
    </collision>
    <collision>
      <origin xyz="0 0 0" rpy="1.5707963 0 0" />
      <geometry>
        <mesh filename="meshes/part_106_solid_106.stl" scale="0.001 0.001 0.001" />
      </geometry>
    </collision>
    <collision>
      <origin xyz="0 0 0" rpy="1.5707963 0 0" />
      <geometry>
        <mesh filename="meshes/part_107_solid_107.stl" scale="0.001 0.001 0.001" />
      </geometry>
    </collision>
    <collision>
      <origin xyz="0 0 0" rpy="1.5707963 0 0" />
      <geometry>
        <mesh filename="meshes/part_108_solid_108.stl" scale="0.001 0.001 0.001" />
      </geometry>
    </collision>
    <collision>
      <origin xyz="0 0 0" rpy="1.5707963 0 0" />
      <geometry>
        <mesh filename="meshes/part_109_solid_109.stl" scale="0.001 0.001 0.001" />
      </geometry>
    </collision>
    <collision>
      <origin xyz="0 0 0" rpy="1.5707963 0 0" />
      <geometry>
        <mesh filename="meshes/part_110_solid_110.stl" scale="0.001 0.001 0.001" />
      </geometry>
    </collision>
    <collision>
      <origin xyz="0 0 0" rpy="1.5707963 0 0" />
      <geometry>
        <mesh filename="meshes/part_111_solid_111.stl" scale="0.001 0.001 0.001" />
      </geometry>
    </collision>
    <collision>
      <origin xyz="0 0 0" rpy="1.5707963 0 0" />
      <geometry>
        <mesh filename="meshes/part_112_solid_112.stl" scale="0.001 0.001 0.001" />
      </geometry>
    </collision>
    <collision>
      <origin xyz="0 0 0" rpy="1.5707963 0 0" />
      <geometry>
        <mesh filename="meshes/part_113_solid_113.stl" scale="0.001 0.001 0.001" />
      </geometry>
    </collision>
    <collision>
      <origin xyz="0 0 0" rpy="1.5707963 0 0" />
      <geometry>
        <mesh filename="meshes/part_114_solid_114.stl" scale="0.001 0.001 0.001" />
      </geometry>
    </collision>
    <collision>
      <origin xyz="0 0 0" rpy="1.5707963 0 0" />
      <geometry>
        <mesh filename="meshes/part_115_solid_115.stl" scale="0.001 0.001 0.001" />
      </geometry>
    </collision>
    <collision>
      <origin xyz="0 0 0" rpy="1.5707963 0 0" />
      <geometry>
        <mesh filename="meshes/part_116_solid_116.stl" scale="0.001 0.001 0.001" />
      </geometry>
    </collision>
    <collision>
      <origin xyz="0 0 0" rpy="1.5707963 0 0" />
      <geometry>
        <mesh filename="meshes/part_117_solid_117.stl" scale="0.001 0.001 0.001" />
      </geometry>
    </collision>
    <collision>
      <origin xyz="0 0 0" rpy="1.5707963 0 0" />
      <geometry>
        <mesh filename="meshes/part_118_solid_118.stl" scale="0.001 0.001 0.001" />
      </geometry>
    </collision>
    <collision>
      <origin xyz="0 0 0" rpy="1.5707963 0 0" />
      <geometry>
        <mesh filename="meshes/part_120_solid_120.stl" scale="0.001 0.001 0.001" />
      </geometry>
    </collision>
    <collision>
      <origin xyz="0 0 0" rpy="1.5707963 0 0" />
      <geometry>
        <mesh filename="meshes/part_121_solid_121.stl" scale="0.001 0.001 0.001" />
      </geometry>
    </collision>
    <collision>
      <origin xyz="0 0 0" rpy="1.5707963 0 0" />
      <geometry>
        <mesh filename="meshes/part_122_solid_122.stl" scale="0.001 0.001 0.001" />
      </geometry>
    </collision>
    <collision>
      <origin xyz="0 0 0" rpy="1.5707963 0 0" />
      <geometry>
        <mesh filename="meshes/part_123_solid_123.stl" scale="0.001 0.001 0.001" />
      </geometry>
    </collision>
    <collision>
      <origin xyz="0 0 0" rpy="1.5707963 0 0" />
      <geometry>
        <mesh filename="meshes/part_125_solid_125.stl" scale="0.001 0.001 0.001" />
      </geometry>
    </collision>
  </link>
  <joint name="arm_link1_joint" type="revolute">
    <origin xyz="0.22962916 0 -0.54062108" rpy="0 0 0" />
    <parent link="arm_base_link" />
    <child link="arm_link1" />
    <axis xyz="0 0 1" />
    <limit lower="-3.14" upper="3.14" effort="10" velocity="5" />
  </joint>
  <joint name="arm_link2_joint" type="revolute">
    <origin xyz="-0.20297144 0 0.014828559" rpy="0 0 0" />
    <parent link="arm_link1" />
    <child link="arm_link2" />
    <axis xyz="-1 0 0" />
    <limit lower="-1.57" upper="1.57" effort="10" velocity="5" />
  </joint>
  <joint name="arm_link3_joint" type="revolute">
    <origin xyz="0.090171439 1.0840491e-07 0.87750026" rpy="0 0 0" />
    <parent link="arm_link2" />
    <child link="arm_link3" />
    <axis xyz="1 0 0" />
    <limit lower="-3.14" upper="3.14" effort="10" velocity="5" />
  </joint>
  <joint name="arm_link4_joint" type="revolute">
    <origin xyz="0.007000002 -1.0840491e-07 0.78799974" rpy="0 0 0" />
    <parent link="arm_link3" />
    <child link="arm_link4" />
    <axis xyz="-1 0 0" />
    <limit lower="-3.14" upper="3.14" effort="10" velocity="5" />
  </joint>
  <joint name="arm_link5_joint" type="revolute">
    <origin xyz="-0.0635 0 0.011899878" rpy="0 0 0" />
    <parent link="arm_link4" />
    <child link="arm_link5" />
    <axis xyz="0 0 1" />
    <limit lower="-3.14" upper="3.14" effort="10" velocity="5" />
  </joint>
  <joint name="arm_link6_joint" type="revolute">
    <origin xyz="-0.06425 0 0.12260012" rpy="0 0 0" />
    <parent link="arm_link5" />
    <child link="arm_link6" />
    <axis xyz="1 0 0" />
    <limit lower="-3.14" upper="3.14" effort="10" velocity="5" />
  </joint>
  <joint name="hooker_joint" type="fixed">
    <origin xyz="0.0039208355 0 -1.2742075" rpy="0 0 0" />
    <parent link="arm_link6" />
    <child link="hooker_link" />
  </joint>
</robot>